Failure # 1 (occurred at 2022-02-03_20-08-49)
Traceback (most recent call last):
  File "/home/huanting/SuperSonic/third_party/ray/tune/trial_runner.py", line 468, in _process_trial
    result = self.trial_executor.fetch_result(trial)
  File "/home/huanting/SuperSonic/third_party/ray/tune/ray_trial_executor.py", line 430, in fetch_result
    result = ray.get(trial_future[0], DEFAULT_GET_TIMEOUT)
  File "/home/huanting/SuperSonic/third_party/ray/worker.py", line 1474, in get
    raise value.as_instanceof_cause()
ray.exceptions.RayTaskError: [36mray::ARSTrainer.train()[39m (pid=92733, ip=192.168.188.130)
  File "python/ray/_raylet.pyx", line 446, in ray._raylet.execute_task
  File "python/ray/_raylet.pyx", line 400, in ray._raylet.execute_task.function_executor
  File "/home/huanting/SuperSonic/third_party/ray/rllib/agents/trainer.py", line 497, in train
    raise e
  File "/home/huanting/SuperSonic/third_party/ray/rllib/agents/trainer.py", line 486, in train
    result = Trainable.train(self)
  File "/home/huanting/SuperSonic/third_party/ray/tune/trainable.py", line 261, in train
    result = self._train()
  File "/home/huanting/SuperSonic/third_party/ray/rllib/agents/ars/ars.py", line 230, in _train
    results, num_episodes, num_timesteps = self._collect_results(
  File "/home/huanting/SuperSonic/third_party/ray/rllib/agents/ars/ars.py", line 339, in _collect_results
    for result in ray.get(rollout_ids):
ray.exceptions.RayActorError: The actor died unexpectedly before finishing this task.

